Workbook

Sheet Summary
A1: MGNREGA Use-Case Test Report — Megh One AI
A2: Test date 2026-09-26 · 30 use cases from 'Test_Case_Results_21st_Sep_26_MGNREGA (1).csv' (DATA-001 … DATA-030)
A4: Result (per use case)
A5: Use cases tested | B5: =COUNTA('Test Results'!$A$2:$A$31) -> 30
A6: PASSED | B6: =COUNTIF('Test Results'!$K$2:$K$31,"PASS") -> 16
A7: FAILED | B7: =COUNTIF('Test Results'!$K$2:$K$31,"FAIL") -> 14
A8: Pass rate | B8: =B6/B5 -> 0.53333333
A10: Comparison with the testers' 21 Sep status
B11: 21 Sep (testers) | C11: 26 Sep (this test)
A12: Passed | B12: =COUNTIF('Test Results'!$M$2:$M$31,"Passed") -> 17 | C12: =COUNTIF('Test Results'!$K$2:$K$31,"PASS") -> 16
A13: Failed | B13: =COUNTIF('Test Results'!$M$2:$M$31,"Failed") -> 12 | C13: =COUNTIF('Test Results'!$K$2:$K$31,"FAIL") -> 14
A14: On-Hold | B14: =COUNTIF('Test Results'!$M$2:$M$31,"On-Hold") -> 1 | C14: 0
A15: Fixed since 21 Sep (Failed/On-Hold → PASS) | B15: =COUNTIF('Test Results'!$N$2:$N$31,"fixed") -> 1
A16: Passed 21 Sep but FAIL now (newly found: DATA-017 scheme prompt, DATA-021 wrong number) | B16: =COUNTIF('Test Results'!$N$2:$N$31,"newly found (passed 21 Sep)") -> 2
A17: Still failing (Failed or On-Hold on 21 Sep) | B17: =COUNTIF('Test Results'!$N$2:$N$31,"still failing")+COUNTIF('Test Results'!$N$2:$N$31,"On-Hold*") -> 12
A19: DB vs raw data
A20: Reconciliation measures that match (statewide totals) | B20: =COUNTIF('DB vs Raw'!$F$5:$F$18,"Yes")&" of "&COUNTA('DB vs Raw'!$F$5:$F$18) -> 14 of 14
A21: Row counts and every statewide total are identical. One village (GENAPARA, code 274268) is mapped to a different district/block in the DB than in the raw file — see 'DB vs Raw' and Defect 10. For every test figure, the megh_db and raw values are shown side by side on 'Test Results'.
A23: How the test was run
A24: 1. Each use-case template was filled with concrete values — the testers' own 21 Sep example where the sheet gives one (MAWKYRWAT block, SOUTH TURA, DAMASH, JAKREM, MAWRYNGKNENG), plus extra variants where a different case matters (duplicate village names, short FY '25-26', constituency). 43 queries in total (41 for the 30 use cases + 2 diagnostics).
A25: 2. Every query was put to the real bot pipeline (app.pipeline.answer_question — the function behind POST /api/query) with the live model gateway and megh_db. When the bot paused with one-tap options, the option an officer would pick was clicked (MGNREGA; block; the named district; whole constituency).
A26: 3. The full set was run twice (run 1, run 2); DATA-029 was run 5 times because it was intermittent. A use case PASSES only if every one of its queries gives the correct figure in both runs, without an unnecessary 'which scheme?' prompt for an MGNREGA-only measure (the criterion the testers used on 21 Sep).
A27: 4. The expected figure for every query was computed independently twice: (a) read-only SQL on megh_db.curated.v_employment / v_expenditure, and (b) pandas on the raw CSVs. Bot figures were matched against both, allowing only display rounding (lakh ↔ crore).
A28: 5. Every answer was also read by hand; the 'Failure reason / remarks' column gives the exact bot text, the correct value and, where found, the code-level root cause.
A29: 6. Photo proofs: one PNG per query in the 'Evidence' sheet (and docs/MGNREGA_UseCase_Evidence_2026-09-26). Each is a capture of that run — officer turns, chips clicked, the bot's reply verbatim, the SQL it executed, and the Bot vs megh_db vs raw table. They are rendered from the graded run rather than taken as browser screenshots, so the photo always shows the exact answer that was graded.
A30: Units: MGNREGA expenditure is stored in LAKH ₹ (1 crore = 100 lakh). Years are financial years (2024-25 = Apr 2024 – Mar 2025).
A32: Failed use cases at a glance
A33: DATA-003 | B33: Block sharing a village's name: 'couldn't build a working query' (Defect 1)
A34: DATA-004 | B34: SOUTH TURA constituency rejected as out-of-scope (Defect 2)
A35: DATA-011 | B35: Asks which scheme for material expenditure (Defect 3); figure correct after choosing
A36: DATA-013 | B36: Refuses admin expenditure; data is 0 at source (Defect 9, product decision)
A37: DATA-014 | B37: SOUTH TURA out-of-scope; NONGKREM returns codes and counts zero-employment villages (Defects 2, 5)
A38: DATA-016 | B38: WRONG NUMBER: MAWKYRWAT block answered with the village figure, 273 vs 11,590 (Defect 1)
A39: DATA-017 | B39: Asks which scheme for women employment (Defect 3); figure correct after choosing
A40: DATA-019 | B40: Asks which scheme for women % (Defect 3); figure correct after choosing
A41: DATA-020 | B41: Block sharing a village's name: 'couldn't build a working query' (Defect 1)
A42: DATA-021 | B42: WRONG NUMBER: 38.00 instead of 38.16 (integer division, Defect 4)
A43: DATA-023 | B43: No figures given for wages vs materials (Defect 6)
A44: DATA-028 | B44: Routed to reference documents; JAKREM treated as a scheme (Defect 7)
... A46: DATA-030 | B46: Asks which scheme for 'employment generated' (Defect 3); figures correct after choosing

Sheet Test Results
A1: TC ID | B1: Test Scenario | C1: Test Input / Action (sheet) | D1: Expected Result (sheet) | E1: Concrete query tested (2026-09-26) | F1: Bot answer (final turn) | G1: megh_db value | H1: Raw CSV value | I1: DB = Raw? | J1: Numbers correct? | K1: Status 26 Sep (this test) | L1: Failure reason / remarks | M1: Tester status 21 Sep | N1: Change vs 21 Sep | O1: Evidence (photo)
A2: DATA-001 | B2: Village + Year expenditure | C2: What was the total expenditure in [village] during [year]? | D2: Return Total_Exp for that village/year. | E2: (a) What was the total expenditure in DAMASH during 2024-25? → chips clicked: MGNREGA (rural employment) (b) What was the total expenditure in JAKREM during 25-26? → chips clicked: MGNREGA (rural employment) (c) What was the total expenditure in ASIMGRE village of East Garo Hills during 2024-25? → chips clicked: MGNREGA (rural employment) | F2: (a) The total expenditure in Damash during FY 2024-25 for MGNREGA was 216.48 lakh. (b) The total expenditure in Jakrem for FY 2025-26 under MGNREGA was 337.93 lakh. (c) The total expenditure in Asimgre village of East Garo Hills during FY 2024-25 for MGNREGA was 9.38 lakh. | G2: (a) Total expenditure (lakh): 216.48 lakh (b) Total expenditure (lakh): 337.93 lakh (c) Total expenditure (lakh): 9.38 lakh | H2: (a) Total expenditure (lakh): 216.48 lakh (b) Total expenditure (lakh): 337.93 lakh (c) Total expenditure (lakh): 9.38 lakh | I2: Yes | J2: (a) Yes (b) Yes (c) Yes | K2: PASS | L2: (a) PASS — 216.48 lakh = DB 216.48 = raw 216.48. (Bot asks which scheme first: acceptable for the generic word 'expenditure'.) (b) PASS — Short FY '25-26' understood as FY 2025-26; 337.93 lakh = DB = raw. (c) PASS — Duplicate village name (ASIMGRE is 6 villages) + district given: returns the village figure 9.38 lakh, not the district total. | M2: Passed | N2: still passing | O2: See Evidence: DATA-001a, DATA-001b, DATA-001c
A3: DATA-002 | B3: District + Year expenditure | C3: What was the total expenditure in [district] during [year]? | D3: Aggregate Total_Exp for district/year. | E3: (a) What was the total expenditure in West Garo Hills during 2024-25? → chips clicked: MGNREGA (rural employment) (b) What was the total expenditure in East Khasi Hills during 2023-24? → chips clicked: MGNREGA (rural employment) | F3: (a) The total expenditure in West Garo Hills during FY 2024-25 for MGNREGA was 257.01 crore. (b) The total expenditure in East Khasi Hills during FY 2023-24 for MGNREGA was 89.96 crore. | G3: (a) Total expenditure (lakh): 25,701.49 lakh (b) Total expenditure (lakh): 8,996.36 lakh | H3: (a) Total expenditure (lakh): 25,701.49 lakh (b) Total expenditure (lakh): 8,996.36 lakh | I3: Yes | J3: (a) Yes (b) Yes | K3: PASS | L3: (a) PASS — 257.01 crore = 25,701.49 lakh = DB = raw. (b) PASS — 89.96 crore (run 1) / 8,996.36 lakh (run 2) = DB = raw. Unit choice varies between runs. | M3: Passed | N3: still passing | O3: See Evidence: DATA-002a, DATA-002b
A4: DATA-003 | B4: Block + Year expenditure | C4: What was the total expenditure in [block] during [year]? | D4: Aggregate Total_Exp for block/year. | E4: (a) What was the total expenditure in MAWKYRWAT during 2024-25 for MGNREGA, the block, not the village (b) What was the total expenditure in MAWKYRWAT during 2024-25? → chips clicked: MGNREGA (rural employment); The MAWKYRWAT block (c, diagnostic) What was the total expenditure in Mawkyrwat block during 2024-25? → chips clicked: MGNREGA (rural employment) | F4: (a) I understood the question but couldn't build a working query for it against the current MGNREGA data. Try rephrasing it, or ask for a simpler breakdown first (e.g. "PMAY-G sanctions by district for 2023"). (b) I understood the question but couldn't build a working query for it against the current MGNREGA data. Try rephrasing it, or ask for a simpler breakdown first (e.g. "PMAY-G sanctions by district for 2023"). (c, diagnostic) The total expenditure in Mawkyrwat block during FY 2024-25 for MGNREGA was 40.79 crore. | G4: (a) Total expenditure (lakh): 4,079 lakh (b) Total expenditure (lakh): 4,079 lakh (c, diagnostic) Total expenditure (lakh): 4,079 lakh | H4: (a) Total expenditure (lakh): 4,079 lakh (b) Total expenditure (lakh): 4,079 lakh (c, diagnostic) Total expenditure (lakh): 4,079 lakh | I4: Yes | J4: (a) No answer (b) No answer (c, diagnostic) Yes | K4: FAIL | L4: (a) FAIL — Tester's exact query. Both runs: "I understood the question but couldn't build a working query". Expected 4,079.00 lakh (DB = raw). root cause: _explicit_level_in (app/pipeline.py) detects the stated admin level finest-first, so the bot's own chip text '…, the block, not the village' was read as level = VILLAGE (the negated word won); resolve_entities then pinned MAWKYRWAT to village_code 277399 and the block SQL was rejected by the village guard or answered for the village (b) FAIL — Bot correctly asks block vs village, but after clicking its own 'The MAWKYRWAT block' chip it says "couldn't build a working query". Expected 4,079.00 lakh. root cause: _explicit_level_in (app/pipeline.py) detects the stated admin level finest-first, so the bot's own chip text '…, the block, not the village' was read as level = VILLAGE (the negated word won); resolve_entities then pinned MAWKYRWAT to village_code 277399 and the block SQL was rejected by the village guard or answered for the village (c, diagnostic) PASS — Diagnostic: natural wording 'Mawkyrwat block' works: 40.79 crore = 4,079.00 lakh (DB = raw). | M4: Failed | N4: still failing | O4: See Evidence: DATA-003a, DATA-003b, DATA-003c
A5: DATA-004 | B5: Constituency + Year employment | C5: How many persons received employment in [assembly_constituency] during [year]? | D5: Aggregate Employment Provided Persons. | E5: (a) How many persons received employment in SOUTH TURA during 2024-25? (b) How many persons received employment in GAMBEGRE constituency during 2024-25? → chips clicked: The whole GAMBEGRE constituency | F5: (a) I'm Megh One AI, the assistant for Meghalaya's MGNREGA, PMAY-G, Focus Plus, CM Elevate, Focus Legacy (producer groups) and CM Elevate Legacy (sanctions and disbursements) schemes. I can only answer questions about those schemes and their data in Meghalaya — not other topics, other states, or places outside Meghalaya. (b) 8,623 persons received employment in GAMBEGRE constituency during FY 2024-25. | G5: (a) Persons employed: 152 (b) Persons employed: 8,623 | H5: (a) Persons employed: 152 (b) Persons employed: 8,623 | I5: Yes | J5: (a) No answer (b) Yes | K5: FAIL | L5: (a) FAIL — Tester's exact query. SOUTH TURA is rejected as out of scope (edge reply) in both runs. Expected 152 persons (DB = raw; SOUTH TURA has a single village in the data, SANGSANGGRE). (b) PASS — Bot asks whole constituency vs part (reasonable, AC spans 2 districts); whole-AC answer 8,623 = DB = raw. | M5: Failed | N5: still failing | O5: See Evidence: DATA-004a, DATA-004b
A6: DATA-005 | B6: Village employment | C6: How many households received employment in [village]? | D6: Return Employment Provided Households. | E6: (a) How many households received employment in DAMASH during 24-25? (b) How many households received employment in UMDOH 18TH MILE during 2024-25? | F6: (a) 433 households received employment in Damash during FY 2024-25. (b) 38 households received employment in Umdoh 18Th Mile during FY 2024-25. | G6: (a) Households employed: 433 (b) Households employed: 38 | H6: (a) Households employed: 433 (b) Households employed: 38 | I6: Yes | J6: (a) Yes (b) Yes | K6: PASS | L6: (a) PASS — Tester's 14 Sep query ('24-25'): 433 households = DB = raw. (b) PASS — UMDOH 18TH MILE (the '18TH MILE UMDOH' village): 38 = DB = raw (2 source rows, 38 + 0, summed correctly). | M6: Passed | N6: still passing | O6: See Evidence: DATA-005a, DATA-005b
A7: DATA-006 | B7: Village person-days | C7: How many person-days were generated in [village]? | D7: Return Employment Provided Total Person Days. | E7: How many person-days were generated in JAKREM during 2024-25? | F7: Jakrem generated 57,391 person-days in FY 2024-25. | G7: Person-days: 57,391 | H7: Person-days: 57,391 | I7: Yes | J7: Yes | K7: PASS | L7: PASS — 57,391 person-days = DB = raw. | M7: Passed | N7: still passing | O7: See Evidence: DATA-006a
A8: DATA-007 | B8: Village job cards | C8: How many job cards were issued in [village]? | D8: Return Job Cards Issued Total. | E8: How many job cards were issued in DAMASH during 2024-25? | F8: 436 job cards were issued in Damash during FY 2024-25. | G8: Job cards: 436 | H8: Job cards: 436 | I8: Yes | J8: Yes | K8: PASS | L8: PASS — 436 job cards = DB = raw. | M8: Passed | N8: still passing | O8: See Evidence: DATA-007a
A9: DATA-008 | B9: Village women employment | C9: How many women were provided employment in [village]? | D9: Return Women Employment Provided. | E9: How many women were provided employment in DAMASH during 2024-25? | F9: 308 women were provided employment in Damash during FY 2024-25. | G9: Women employed: 308 | H9: Women employed: 308 | I9: Yes | J9: Yes | K9: PASS | L9: PASS — 308 women = DB = raw. | M9: Passed | N9: still passing | O9: See Evidence: DATA-008a
A10: DATA-009 | B10: 100-day completion | C10: How many households completed 100 days in [village]? | D10: Return Households Completed 100 Days Work. | E10: How many households completed 100 days in JAKREM during 2025-26? | F10: 585 households completed 100 days. | G10: HH completed 100 days: 585 | H10: HH completed 100 days: 585 | I10: Yes | J10: Yes | K10: PASS | L10: PASS — 585 households = DB = raw. Minor: answer text omits the village and year. | M10: Passed | N10: still passing | O10: See Evidence: DATA-009a
A11: DATA-010 | B11: Unskilled wages | C11: How much was spent on unskilled wages in [village] during [year]? | D11: Return Exp_Unskilled_Wage. | E11: How much was spent on unskilled wages in DAMASH during 2024-25? | F11: Damash spent 145.35 lakh on unskilled wages during FY 2024-25. | G11: Unskilled wage exp (lakh): 145.35 lakh | H11: Unskilled wage exp (lakh): 145.35 lakh | I11: Yes | J11: Yes | K11: PASS | L11: PASS — 145.35 lakh = DB = raw. | M11: Passed | N11: still passing | O11: See Evidence: DATA-010a
A12: DATA-011 | B12: Materials | C12: How much was spent on materials in [village] during [year]? | D12: Return Exp_Material. | E12: How much was spent on materials in JAKREM during 2024-25? → chips clicked: MGNREGA (rural employment) | F12: Material expenditure in Jakrem for FY 2024-25 was 113.89 lakh. | G12: Material exp (lakh): 113.89 lakh | H12: Material exp (lakh): 113.89 lakh | I12: Yes | J12: Yes (after chip) | K12: FAIL | L12: FAIL — Figure is right after choosing MGNREGA (113.89 lakh = DB = raw), but the bot first asks 'Which scheme does your question concern?' although this measure exists only in MGNREGA (same defect the testers logged on 21 Sep). | M12: Failed | N12: still failing | O12: See Evidence: DATA-011a
... A31: DATA-030 | B31: District expenditure + employment | C31: Compare total expenditure and employment generated in [district] during [year]. | D31: Return expenditure and employment metrics from both datasets. | E31: Compare total expenditure and employment generated in West Garo Hills during 2024-25. → chips clicked: MGNREGA (rural employment) | F31: West Garo Hills recorded a total expenditure of 257.01 crore and generated 2,808,417 person days during FY 2024-25. | G31: Total expenditure (lakh): 25,701.49 lakh Person-days: 2,808,417 | H31: Total expenditure (lakh): 25,701.49 lakh Person-days: 2,806,403 | I31: No (GENAPARA) | J31: Yes (after chip) | K31: FAIL | L31: FAIL — Figures right after choosing MGNREGA (257.01 crore = DB = raw; 2,808,417 person-days = DB, raw 2,806,403 because of the GENAPARA mapping), but the bot first asks 'Which scheme does your question concern?' although this measure exists only in MGNREGA (same defect the testers logged on 21 Sep). | M31: Failed | N31: still failing | O31: See Evidence: DATA-030a

Sheet Variant Detail
A1: Variant | B1: TC ID | C1: Diagnostic? | D1: Question asked | E1: Chips clicked (bot pauses) | F1: Final route | G1: Bot answer — run 1 | H1: Bot answer — run 2 | I1: SQL executed (run 1) | J1: Metric | K1: Bot matched DB/raw? | L1: megh_db | M1: Raw CSV | N1: Verdict | O1: Reason | P1: Evidence
A2: DATA-001a | B2: DATA-001 | D2: What was the total expenditure in DAMASH during 2024-25? | E2: MGNREGA (rural employment) | F2: data | G2: The total expenditure in Damash during FY 2024-25 for MGNREGA was 216.48 lakh. | H2: The total expenditure in Damash during FY 2024-25 for MGNREGA was 216.48 lakh. | I2: SELECT SUM(total_exp) AS total_expenditure_lakh FROM curated.v_expenditure WHERE village_code = 274695 AND year_key = 2024 LIMIT 1 | J2: Total expenditure (lakh) | K2: Yes | L2: 216.48 lakh | M2: 216.48 lakh | N2: PASS | O2: 216.48 lakh = DB 216.48 = raw 216.48. (Bot asks which scheme first: acceptable for the generic word 'expenditure'.) | P2: DATA-001a.png
A3: DATA-001b | B3: DATA-001 | D3: What was the total expenditure in JAKREM during 25-26? | E3: MGNREGA (rural employment) | F3: data | G3: The total expenditure in Jakrem for FY 2025-26 under MGNREGA was 337.93 lakh. | H3: The total expenditure in Jakrem for FY 2025-26 under MGNREGA was 337.93 lakh. | I3: SELECT SUM(total_exp) AS total_expenditure_lakh FROM curated.v_expenditure WHERE village_code = 277391 AND year_key = 2025 LIMIT 1 | J3: Total expenditure (lakh) | K3: Yes | L3: 337.93 lakh | M3: 337.93 lakh | N3: PASS | O3: Short FY '25-26' understood as FY 2025-26; 337.93 lakh = DB = raw. | P3: DATA-001b.png
A4: DATA-001c | B4: DATA-001 | D4: What was the total expenditure in ASIMGRE village of East Garo Hills during 2024-25? | E4: MGNREGA (rural employment) | F4: data | G4: The total expenditure in Asimgre village of East Garo Hills during FY 2024-25 for MGNREGA was 9.38 lakh. | H4: The total expenditure in Asimgre village of East Garo Hills during FY 2024-25 for MGNREGA was 9.38 lakh. | I4: SELECT SUM(total_exp) AS total_expenditure_lakh FROM curated.v_expenditure WHERE year_key = 2024 AND village_code = 275373 LIMIT 1 | J4: Total expenditure (lakh) | K4: Yes | L4: 9.38 lakh | M4: 9.38 lakh | N4: PASS | O4: Duplicate village name (ASIMGRE is 6 villages) + district given: returns the village figure 9.38 lakh, not the district total. | P4: DATA-001c.png
A5: DATA-002a | B5: DATA-002 | D5: What was the total expenditure in West Garo Hills during 2024-25? | E5: MGNREGA (rural employment) | F5: data | G5: The total expenditure in West Garo Hills during FY 2024-25 for MGNREGA was 257.01 crore. | H5: The total expenditure in West Garo Hills during FY 2024-25 for MGNREGA was 257.01 crore. | I5: SELECT ROUND(SUM(total_exp) / 100, 2) AS total_expenditure_crore FROM curated.v_expenditure WHERE year_key = 2024 AND lgd_district = 'WEST GARO HILLS' LIMIT 1 | J5: Total expenditure (lakh) | K5: Yes | L5: 25,701.49 lakh | M5: 25,701.49 lakh | N5: PASS | O5: 257.01 crore = 25,701.49 lakh = DB = raw. | P5: DATA-002a.png
A6: DATA-002b | B6: DATA-002 | D6: What was the total expenditure in East Khasi Hills during 2023-24? | E6: MGNREGA (rural employment) | F6: data | G6: The total expenditure in East Khasi Hills during FY 2023-24 for MGNREGA was 89.96 crore. | H6: The total expenditure in East Khasi Hills during FY 2023-24 for MGNREGA was 8996.36 lakh. | I6: SELECT ROUND(SUM(total_exp) / 100, 2) AS total_expenditure_crore FROM curated.v_expenditure WHERE year_key = 2023 AND lgd_district = 'EAST KHASI HILLS' LIMIT 1 | J6: Total expenditure (lakh) | K6: Yes | L6: 8,996.36 lakh | M6: 8,996.36 lakh | N6: PASS | O6: 89.96 crore (run 1) / 8,996.36 lakh (run 2) = DB = raw. Unit choice varies between runs. | P6: DATA-002b.png
A7: DATA-003a | B7: DATA-003 | D7: What was the total expenditure in MAWKYRWAT during 2024-25 for MGNREGA, the block, not the village | E7: (none) | F7: data | G7: I understood the question but couldn't build a working query for it against the current MGNREGA data. Try rephrasing it, or ask for a simpler breakdown first (e.g. "PMAY-G sanctions by district for 2023"). | H7: I understood the question but couldn't build a working query for it against the current MGNREGA data. Try rephrasing it, or ask for a simpler breakdown first (e.g. "PMAY-G sanctions by district for 2023"). | J7: Total expenditure (lakh) | K7: No | L7: 4,079 lakh | M7: 4,079 lakh | N7: FAIL | O7: Tester's exact query. Both runs: "I understood the question but couldn't build a working query". Expected 4,079.00 lakh (DB = raw). root cause: _explicit_level_in (app/pipeline.py) detects the stated admin level finest-first, so the bot's own chip text '…, the block, not the village' was read as level = VILLAGE (the negated word won); resolve_entities then pinned MAWKYRWAT to village_code 277399 and the block SQL was rejected by the village guard or answered for the village | P7: DATA-003a.png
A8: DATA-003b | B8: DATA-003 | D8: What was the total expenditure in MAWKYRWAT during 2024-25? | E8: MGNREGA (rural employment); The MAWKYRWAT block | F8: data | G8: I understood the question but couldn't build a working query for it against the current MGNREGA data. Try rephrasing it, or ask for a simpler breakdown first (e.g. "PMAY-G sanctions by district for 2023"). | H8: I understood the question but couldn't build a working query for it against the current MGNREGA data. Try rephrasing it, or ask for a simpler breakdown first (e.g. "PMAY-G sanctions by district for 2023"). | J8: Total expenditure (lakh) | K8: No | L8: 4,079 lakh | M8: 4,079 lakh | N8: FAIL | O8: Bot correctly asks block vs village, but after clicking its own 'The MAWKYRWAT block' chip it says "couldn't build a working query". Expected 4,079.00 lakh. root cause: _explicit_level_in (app/pipeline.py) detects the stated admin level finest-first, so the bot's own chip text '…, the block, not the village' was read as level = VILLAGE (the negated word won); resolve_entities then pinned MAWKYRWAT to village_code 277399 and the block SQL was rejected by the village guard or answered for the village | P8: DATA-003b.png
A9: DATA-003c | B9: DATA-003 | C9: Yes | D9: What was the total expenditure in Mawkyrwat block during 2024-25? | E9: MGNREGA (rural employment) | F9: data | G9: The total expenditure in Mawkyrwat block during FY 2024-25 for MGNREGA was 40.79 crore. | H9: The total expenditure in Mawkyrwat block during FY 2024-25 for MGNREGA was 40.79 crore. | I9: SELECT ROUND(SUM(total_exp) / 100, 2) AS total_expenditure_crore FROM curated.v_expenditure WHERE lgd_block = 'MAWKYRWAT' AND year_key = 2024 LIMIT 1 | J9: Total expenditure (lakh) | K9: Yes | L9: 4,079 lakh | M9: 4,079 lakh | N9: PASS | O9: Diagnostic: natural wording 'Mawkyrwat block' works: 40.79 crore = 4,079.00 lakh (DB = raw). | P9: DATA-003c.png
A10: DATA-004a | B10: DATA-004 | D10: How many persons received employment in SOUTH TURA during 2024-25? | E10: (none) | F10: edge | G10: I'm Megh One AI, the assistant for Meghalaya's MGNREGA, PMAY-G, Focus Plus, CM Elevate, Focus Legacy (producer groups) and CM Elevate Legacy (sanctions and disbursements) schemes. I can only answer questions about those schemes and their data in Meghalaya — not other topics, other states, or places outside Meghalaya. | H10: I'm Megh One AI, the assistant for Meghalaya's MGNREGA, PMAY-G, Focus Plus, CM Elevate, Focus Legacy (producer groups) and CM Elevate Legacy (sanctions and disbursements) schemes. I can only answer questions about those schemes and their data in Meghalaya — not other topics, other states, or places outside Meghalaya. | J10: Persons employed | K10: No | L10: 152 | M10: 152 | N10: FAIL | O10: Tester's exact query. SOUTH TURA is rejected as out of scope (edge reply) in both runs. Expected 152 persons (DB = raw; SOUTH TURA has a single village in the data, SANGSANGGRE). | P10: DATA-004a.png
A11: DATA-004b | B11: DATA-004 | D11: How many persons received employment in GAMBEGRE constituency during 2024-25? | E11: The whole GAMBEGRE constituency | F11: data | G11: 8,623 persons received employment in GAMBEGRE constituency during FY 2024-25. | H11: 8623 persons received employment in GAMBEGRE constituency during FY 2024-25. | I11: SELECT SUM(persons_employed) AS persons_employed FROM curated.v_employment WHERE year_key = 2024 AND UPPER(assembly_constituency_name) = UPPER('GAMBEGRE') LIMIT 1 | J11: Persons employed | K11: Yes | L11: 8,623 | M11: 8,623 | N11: PASS | O11: Bot asks whole constituency vs part (reasonable, AC spans 2 districts); whole-AC answer 8,623 = DB = raw. | P11: DATA-004b.png
A12: DATA-005a | B12: DATA-005 | D12: How many households received employment in DAMASH during 24-25? | E12: (none) | F12: data | G12: 433 households received employment in Damash during FY 2024-25. | H12: 433 households received employment in Damash during FY 2024-25. | I12: SELECT SUM(households_employed) AS households_employed FROM curated.v_employment WHERE village_code = 274695 AND year_key = 2024 LIMIT 1 | J12: Households employed | K12: Yes | L12: 433 | M12: 433 | N12: PASS | O12: Tester's 14 Sep query ('24-25'): 433 households = DB = raw. | P12: DATA-005a.png
A13: DATA-005b | B13: DATA-005 | D13: How many households received employment in UMDOH 18TH MILE during 2024-25? | E13: (none) | F13: data | G13: 38 households received employment in Umdoh 18Th Mile during FY 2024-25. | H13: 38 households received employment in Umdoh 18Th Mile during FY 2024-25. | I13: SELECT SUM(households_employed) AS households_employed FROM curated.v_employment WHERE village_code = 277515 AND year_key = 2024 LIMIT 1 | J13: Households employed | K13: Yes | L13: 38 | M13: 38 | N13: PASS | O13: UMDOH 18TH MILE (the '18TH MILE UMDOH' village): 38 = DB = raw (2 source rows, 38 + 0, summed correctly). | P13: DATA-005b.png
A14: DATA-006a | B14: DATA-006 | D14: How many person-days were generated in JAKREM during 2024-25? | E14: (none) | F14: data | G14: Jakrem generated 57,391 person-days in FY 2024-25. | H14: Jakrem generated 57,391 person-days in FY 2024-25. | I14: SELECT SUM(person_days) AS person_days FROM curated.v_employment WHERE village_code = 277391 AND year_key = 2024 LIMIT 1 | J14: Person-days | K14: Yes | L14: 57,391 | M14: 57,391 | N14: PASS | O14: 57,391 person-days = DB = raw. | P14: DATA-006a.png
A15: DATA-007a | B15: DATA-007 | D15: How many job cards were issued in DAMASH during 2024-25? | E15: (none) | F15: data | G15: 436 job cards were issued in Damash during FY 2024-25. | H15: 436 job cards were issued in Damash during FY 2024-25. | I15: SELECT SUM(job_cards_issued_total) AS job_card_stock FROM curated.v_employment WHERE year_key = 2024 AND village_code = 274695 LIMIT 1 | J15: Job cards | K15: Yes | L15: 436 | M15: 436 | N15: PASS | O15: 436 job cards = DB = raw. | P15: DATA-007a.png
A16: DATA-008a | B16: DATA-008 | D16: How many women were provided employment in DAMASH during 2024-25? | E16: (none) | F16: data | G16: 308 women were provided employment in Damash during FY 2024-25. | H16: 308 women were provided employment in Damash during FY 2024-25. | I16: SELECT SUM(women_employment_provided) AS women_employment_provided FROM curated.v_employment WHERE village_code = 274695 AND year_key = 2024 LIMIT 1 | J16: Women employed | K16: Yes | L16: 308 | M16: 308 | N16: PASS | O16: 308 women = DB = raw. | P16: DATA-008a.png
A17: DATA-009a | B17: DATA-009 | D17: How many households completed 100 days in JAKREM during 2025-26? | E17: (none) | F17: data | G17: 585 households completed 100 days. | H17: 585 households completed 100 days. | I17: SELECT SUM(households_completed_100_days) AS households_completed_100_days FROM curated.v_employment WHERE village_code = 277391 AND year_key = 2025 LIMIT 1 | J17: HH completed 100 days | K17: Yes | L17: 585 | M17: 585 | N17: PASS | O17: 585 households = DB = raw. Minor: answer text omits the village and year. | P17: DATA-009a.png
A18: DATA-010a | B18: DATA-010 | D18: How much was spent on unskilled wages in DAMASH during 2024-25? | E18: (none) | F18: data | G18: Damash spent 145.35 lakh on unskilled wages during FY 2024-25. | H18: Damash spent 145.35 lakh on unskilled wages during FY 2024-25. | I18: SELECT ROUND(SUM(unskilled_wage_exp), 2) AS unskilled_wage_expenditure_lakh FROM curated.v_expenditure WHERE village_code = 274695 AND year_key = 2024 LIMIT 1 | J18: Unskilled wage exp (lakh) | K18: Yes | L18: 145.35 lakh | M18: 145.35 lakh | N18: PASS | O18: 145.35 lakh = DB = raw. | P18: DATA-010a.png
A19: DATA-011a | B19: DATA-011 | D19: How much was spent on materials in JAKREM during 2024-25? | E19: MGNREGA (rural employment) | F19: data | G19: Material expenditure in Jakrem for FY 2024-25 was 113.89 lakh. | H19: Material expenditure in Jakrem for FY 2024-25 was 113.89 lakh. | I19: SELECT ROUND(SUM(material_exp), 2) AS material_expenditure_lakh FROM curated.v_expenditure WHERE village_code = 277391 AND year_key = 2024 LIMIT 1 | J19: Material exp (lakh) | K19: Yes | L19: 113.89 lakh | M19: 113.89 lakh | N19: FAIL | O19: Figure is right after choosing MGNREGA (113.89 lakh = DB = raw), but the bot first asks 'Which scheme does your question concern?' although this measure exists only in MGNREGA (same defect the testers logged on 21 Sep). | P19: DATA-011a.png
A20: DATA-012a | B20: DATA-012 | D20: How much was spent on semi-skilled wages in DAMASH during 2024-25? | E20: (none) | F20: data | G20: Semi-skilled wages in Damash for FY 2024-25 were 12.67 lakh. | H20: Semi-skilled wages in Damash for FY 2024-25 were 12.67 lakh. | I20: SELECT ROUND(SUM(semi_skilled_wage_exp), 2) AS semi_skilled_wage_exp_lakh FROM curated.v_expenditure WHERE village_code = 274695 AND year_key = 2024 LIMIT 1 | J20: Semi-skilled wage exp (lakh) | K20: Yes | L20: 12.67 lakh | M20: 12.67 lakh | N20: PASS | O20: 12.67 lakh = DB = raw. | P20: DATA-012a.png
A21: DATA-013a | B21: DATA-013 | D21: What was the administrative expenditure in MAWRYNGKNENG during 2024-25? | E21: (none) | F21: clarification | G21: There is no usable administrative-expenditure figure in any scheme I cover. MGNREGA has the column but it was never populated (zero on every row but one statewide), and PMAY-G records only sanctioned and released amounts. Shall I answer using wage, material or total expenditure instead? | H21: There is no usable administrative-expenditure figure in any scheme I cover. MGNREGA has the column but it was never populated (zero on every row but one statewide), and PMAY-G records only sanctioned and released amounts. Shall I answer using wage, material or total expenditure instead? | J21: Admin exp total (lakh) | K21: Yes | L21: 0 lakh | M21: 0 lakh | N21: FAIL | O21: Bot refuses: 'no usable administrative-expenditure figure … zero on every row but one statewide'. That statement is TRUE (DB = raw: Adm_Exp_Total is 0.00 for all 38 MAWRYNGKNENG rows in 2024-25; only 1 row statewide is non-zero, 0.90 lakh), but the test expects the aggregate (0.00 lakh). Refusal is by design (schema rule 10), so this needs a product decision. | P21: DATA-013a.png
A22: DATA-014a | B22: DATA-014 | D22: Which villages in SOUTH TURA received employment during 2024-25? | E22: MGNREGA (rural employment) | F22: edge | G22: I'm Megh One AI, the assistant for Meghalaya's MGNREGA, PMAY-G, Focus Plus, CM Elevate, Focus Legacy (producer groups) and CM Elevate Legacy (sanctions and disbursements) schemes. I can only answer questions about those schemes and their data in Meghalaya — not other topics, other states, or places outside Meghalaya. | H22: I'm Megh One AI, the assistant for Meghalaya's MGNREGA, PMAY-G, Focus Plus, CM Elevate, Focus Legacy (producer groups) and CM Elevate Legacy (sanctions and disbursements) schemes. I can only answer questions about those schemes and their data in Meghalaya — not other topics, other states, or places outside Meghalaya. | J22: Villages with employment | K22: No | L22: SANGSANGGRE | M22: SANGSANGGRE | N22: FAIL | O22: Tester's exact query. Bot asks which scheme, then after MGNREGA replies out-of-scope. Expected: SANGSANGGRE (152 persons), DB = raw. | P22: DATA-014a.png
A23: DATA-014b | B23: DATA-014 | D23: Which villages in NONGKREM constituency received employment during 2024-25? | E23: MGNREGA (rural employment); The whole NONGKREM constituency | F23: data | G23: Four villages in NONGKREM constituency received employment during FY 2024-25 for MGNREGA. The village codes are 278375, 278386, 278399, and 278424. | H23: Four villages in NONGKREM constituency received employment during FY 2024-25 for MGNREGA. The village codes are 278375, 278386, 278399, and 278424. | I23: SELECT DISTINCT village_code FROM curated.v_employment WHERE year_key = 2024 AND UPPER(assembly_constituency_name) = UPPER('NONGKREM') ORDER BY village_code LIMIT 1000 | J23: Villages with employment | K23: No | L23: URMASI-U-JOH | M23: URMASI-U-JOH | N23: FAIL | O23: Says 'Four villages … received employment' and lists 4 village CODES, no names. DB = raw: only URMASI-U-JOH had employment (66 persons); the other 3 have zero. SQL is SELECT DISTINCT village_code with no >0 filter. Also the bot first asks 'Which scheme does your question concern?' although this measure exists only in MGNREGA (same defect the testers logged on 21 Sep). | P23: DATA-014b.png
A24: DATA-015a | B24: DATA-015 | D24: How many total person-days were generated in Ri Bhoi during 2024-25? | E24: (none) | F24: data | G24: Ri Bhoi generated 928,817 person-days during FY 2024-25. | H24: Ri Bhoi generated 928,817 person-days during FY 2024-25. | I24: SELECT SUM(person_days) AS person_days FROM curated.v_employment WHERE year_key = 2024 AND lgd_district = 'RI BHOI' LIMIT 1 | J24: Person-days | K24: Yes | L24: 928,817 | M24: 928,817 | N24: PASS | O24: 928,817 person-days = DB = raw. | P24: DATA-015a.png
A25: DATA-016a | B25: DATA-016 | D25: How many households received employment in MAWKYRWAT during 2024-25, the block, not the village | E25: (none) | F25: data | G25: 273 households received employment in Mawkyrwat during FY 2024-25. | H25: 273 households received employment in Mawkyrwat during FY 2024-25. | I25: SELECT SUM(households_employed) AS households_employed FROM curated.v_employment WHERE village_code = 277399 AND year_key = 2024 LIMIT 1 | J25: Households employed | K25: No | L25: 11,590 | M25: 11,590 | N25: FAIL | O25: Tester's exact query. Bot answers 273 households: that is MAWKYRWAT VILLAGE (SQL: village_code = 277399), although the user said 'the block, not the village'. Correct block figure is 11,590 (DB = raw). Confident wrong number. root cause: _explicit_level_in (app/pipeline.py) detects the stated admin level finest-first, so the bot's own chip text '…, the block, not the village' was read as level = VILLAGE (the negated word won); resolve_entities then pinned MAWKYRWAT to village_code 277399 and the block SQL was rejected by the village guard or answered for the village | P25: DATA-016a.png
A26: DATA-016b | B26: DATA-016 | D26: How many households received employment in Dadenggiri block during 2024-25? | E26: (none) | F26: data | G26: 6,404 households received employment in Dadenggiri block during FY 2024-25. | H26: 6,404 households received employment in Dadenggiri block during FY 2024-25. | I26: SELECT SUM(households_employed) AS households_employed FROM curated.v_employment WHERE lgd_block = 'DADENGGIRI' AND year_key = 2024 LIMIT 1 | J26: Households employed | K26: Yes | L26: 6,404 | M26: 6,404 | N26: PASS | O26: 6,404 households = DB = raw. | P26: DATA-016b.png
A27: DATA-016c | B27: DATA-016 | C27: Yes | D27: How many households received employment in Mawkyrwat block during 2024-25? | E27: (none) | F27: data | G27: 11,590 households received employment in Mawkyrwat block during FY 2024-25. | H27: 11,590 households received employment in Mawkyrwat block during FY 2024-25. | I27: SELECT SUM(households_employed) AS households_employed FROM curated.v_employment WHERE lgd_block = 'MAWKYRWAT' AND year_key = 2024 LIMIT 1 | J27: Households employed | K27: Yes | L27: 11,590 | M27: 11,590 | N27: PASS | O27: Diagnostic: 'Mawkyrwat block' wording gives 11,590 = DB = raw. | P27: DATA-016c.png
A28: DATA-017a | B28: DATA-017 | D28: How many women received employment in West Khasi Hills during 2023-24? | E28: MGNREGA (rural employment) | F28: data | G28: 16,096 women received employment in West Khasi Hills during FY 2023-24 for MGNREGA. | H28: 16,096 women received employment in West Khasi Hills during FY 2023-24 for MGNREGA. | I28: SELECT SUM(women_employment_provided) AS women_employed FROM curated.v_employment WHERE year_key = 2023 AND lgd_district = 'WEST KHASI HILLS' LIMIT 1 | J28: Women employed | K28: Yes | L28: 16,096 | M28: 16,096 | N28: FAIL | O28: Figure is right after choosing MGNREGA (16,096 = DB = raw), but the bot first asks 'Which scheme does your question concern?' although this measure exists only in MGNREGA (same defect the testers logged on 21 Sep). | P28: DATA-017a.png
A29: DATA-018a | B29: DATA-018 | D29: How many job cards were issued in East Garo Hills during 2024-25? | E29: (none) | F29: data | G29: East Garo Hills issued 24,601 job cards in FY 2024-25. | H29: East Garo Hills issued 24,601 job cards in FY 2024-25. | I29: SELECT SUM(job_cards_issued_total) AS job_card_stock FROM curated.v_employment WHERE year_key = 2024 AND lgd_district = 'EAST GARO HILLS' LIMIT 1 | J29: Job cards | K29: Yes | L29: 24,601 | M29: 24,601 | N29: PASS | O29: 24,601 job cards = DB = raw. | P29: DATA-018a.png
A30: DATA-019a | B30: DATA-019 | D30: What percentage of employment persons were women in West Garo Hills during 2024-25? | E30: MGNREGA (rural employment) | F30: data | G30: West Garo Hills had 52.65% women among employment persons in FY 2024-25 for MGNREGA. | H30: West Garo Hills had 52.65% women among employment persons in FY 2024-25 for MGNREGA. | I30: SELECT ROUND(100.0 * SUM(women_employment_provided) / NULLIF(SUM(persons_employed), 0), 2) AS women_share_pct FROM curated.v_employment WHERE year_key = 2024 AND lgd_district = 'WEST GARO HILLS' LIMIT 1 | J30: Women % of persons | K30: Yes | L30: 52.65% [29,890 / 56,774] | M30: 52.64% [29,865 / 56,733] | N30: FAIL | O30: Figure is right after choosing MGNREGA: 52.65% = DB 52.65% (raw 52.64%, see GENAPARA mapping note), but the bot first asks 'Which scheme does your question concern?' although this measure exists only in MGNREGA (same defect the testers logged on 21 Sep). | P30: DATA-019a.png
A31: DATA-020a | B31: DATA-020 | D31: What percentage of employment households completed 100 days in MAWKYRWAT during 2024-25, the block, not the village | E31: (none) | F31: data | G31: I understood the question but couldn't build a working query for it against the current MGNREGA data. Try rephrasing it, or ask for a simpler breakdown first (e.g. "PMAY-G sanctions by district for 2023"). | H31: I understood the question but couldn't build a working query for it against the current MGNREGA data. Try rephrasing it, or ask for a simpler breakdown first (e.g. "PMAY-G sanctions by district for 2023"). | J31: 100-day HH % | K31: No | L31: 3.39% [393 / 11,590] | M31: 3.39% [393 / 11,590] | N31: FAIL | O31: Tester's exact query. "couldn't build a working query" in both runs. Expected 3.39% (393 / 11,590, DB = raw). root cause: _explicit_level_in (app/pipeline.py) detects the stated admin level finest-first, so the bot's own chip text '…, the block, not the village' was read as level = VILLAGE (the negated word won); resolve_entities then pinned MAWKYRWAT to village_code 277399 and the block SQL was rejected by the village guard or answered for the village | P31: DATA-020a.png
A32: DATA-020b | B32: DATA-020 | D32: What percentage of employment households completed 100 days in Dadenggiri block during 2023-24? | E32: (none) | F32: data | G32: 6.67 completion 100 day pct. | H32: 6.67 completion 100 day pct. | I32: SELECT ROUND(100.0 * SUM(households_completed_100_days) / NULLIF(SUM(households_employed), 0), 2) AS completion_100_day_pct FROM curated.v_employment WHERE lgd_block = 'DADENGGIRI' AND year_key = 2023 LIMIT 1 | J32: 100-day HH % | K32: Yes | L32: 6.67% [634 / 9,507] | M32: 6.67% [634 / 9,507] | N32: PASS | O32: 6.67% = DB = raw (634 / 9,507). Minor: answer text is garbled ('6.67 completion 100 day pct.'). | P32: DATA-020b.png
A33: DATA-021a | B33: DATA-021 | D33: What was the average number of person-days per employment household in East Khasi Hills during 2024-25? | E33: (none) | F33: data | G33: East Khasi Hills recorded an average of 38.00 person-days per employment household during FY 2024-25. | H33: East Khasi Hills recorded an average of 38.00 person-days per employment household during FY 2024-25. | I33: SELECT ROUND(SUM(person_days) / NULLIF(SUM(households_employed), 0), 2) AS avg_person_days_per_household FROM curated.v_employment WHERE year_key = 2024 AND lgd_district = 'EAST KHASI HILLS' LIMIT 1 | J33: Person-days per HH | K33: No | L33: 38.16 [1,632,188 / 42,770] | M33: 38.16 [1,632,188 / 42,770] | N33: FAIL | O33: Bot says 38.00; correct is 38.16 (1,632,188 person-days / 42,770 households, DB = raw). SQL divides SUM(bigint)/SUM(bigint), so Postgres does integer division and truncates to 38. | P33: DATA-021a.png
A34: DATA-022a | B34: DATA-022 | D34: Give me the expenditure breakdown for DAMASH during 2024-25. | E34: MGNREGA (rural employment) | F34: data | G34: Total expenditure for Damash in FY 2024-25 was 216.48 lakh, comprising 145.35 lakh in unskilled wages, 12.67 lakh in semi-skilled wages, and 58.46 lakh in materials. | H34: Total expenditure for Damash in FY 2024-25 was 216.48 lakh, comprising 145.35 lakh in unskilled wages, 12.67 lakh in semi-skilled wages, and 58.46 lakh in materials. | I34: SELECT SUM(total_exp) AS total_expenditure_lakh, SUM(unskilled_wage_exp) AS unskilled_wage_exp_lakh, SUM(semi_skilled_wage_exp) AS semi_skilled_wage_exp_lakh, SUM(material_exp) AS material_exp_lakh FROM curated.v_expenditure WHERE village_code = 274695 AND year_key = 2024 LIMIT 1 | J34: Unskilled (lakh) Semi-skilled (lakh) Material (lakh) Total (lakh) | K34: Yes Yes Yes Yes | L34: 145.35 lakh 12.67 lakh 58.46 lakh 216.48 lakh | M34: 145.35 lakh 12.67 lakh 58.46 lakh 216.48 lakh | N34: PASS | O34: Unskilled 145.35 + semi-skilled 12.67 + material 58.46 = total 216.48 lakh, all = DB = raw. | P34: DATA-022a.png
A35: DATA-023a | B35: DATA-023 | D35: Was more spent on wages or materials in JAKREM during 2024-25? | E35: MGNREGA (rural employment) | F35: data | G35: Wages were the higher spending category in Jakrem for FY 2024-25. The result indicates wages exceeded materials, with no specific monetary figures provided in the available data. | H35: More was spent on wages than on materials in Jakrem during FY 2024-25. The data indicates wages as the higher spending category. | I35: SELECT CASE WHEN SUM(unskilled_wage_exp + semi_skilled_wage_exp) > SUM(material_exp) THEN 'wages' ELSE 'materials' END AS higher_spending_category FROM curated.v_expenditure WHERE village_code = 277391 AND year_key = 2024 LIMIT 1 | J35: Wages = unskilled+semi (lakh) Material (lakh) | K35: No No | L35: 219.48 lakh 113.89 lakh | M35: 219.48 lakh 113.89 lakh | N35: FAIL | O35: Says wages were higher (correct direction) but gives NO amounts (wages 219.48 vs materials 113.89 lakh, DB = raw); run 1 even claims 'no specific monetary figures provided in the available data', which is false. Also the bot first asks 'Which scheme does your question concern?' although this measure exists only in MGNREGA (same defect the testers logged on 21 Sep). | P35: DATA-023a.png
A36: DATA-024a | B36: DATA-024 | D36: Which district had the highest expenditure during 2024-25? | E36: MGNREGA (rural employment) | F36: data | G36: WEST GARO HILLS had the highest expenditure of 257.01 crore during FY 2024-25. | H36: WEST GARO HILLS had the highest expenditure of 257.01 crore during FY 2024-25. | I36: SELECT lgd_district, ROUND(SUM(total_exp) / 100, 2) AS total_expenditure_crore FROM curated.v_expenditure WHERE year_key = 2024 GROUP BY lgd_district ORDER BY total_expenditure_crore DESC LIMIT 1 | J36: Top district by expenditure | K36: Yes | L36: WEST GARO HILLS (25,701.49) | M36: WEST GARO HILLS (25,701.49) | N36: PASS | O36: WEST GARO HILLS, 257.01 crore = DB = raw (runner-up SWGH 138.23 crore). | P36: DATA-024a.png
A37: DATA-024b | B37: DATA-024 | D37: Which district had the highest expenditure for MGNREGA during 2023-24? | E37: (none) | F37: data | G37: WEST GARO HILLS had the highest expenditure of 148.81 crore for MGNREGA during FY 2023-24. | H37: WEST GARO HILLS had the highest expenditure of 148.81 crore for MGNREGA during FY 2023-24. | I37: SELECT lgd_district, ROUND(SUM(total_exp) / 100, 2) AS total_expenditure_crore FROM curated.v_expenditure WHERE year_key = 2023 GROUP BY lgd_district ORDER BY total_expenditure_crore DESC LIMIT 1 | J37: Top district by expenditure | K37: Yes | L37: WEST GARO HILLS (14,880.51) | M37: WEST GARO HILLS (14,880.51) | N37: PASS | O37: WEST GARO HILLS, 148.81 crore = DB = raw. | P37: DATA-024b.png
A38: DATA-025a | B38: DATA-025 | D38: Which block generated the highest person-days during 2024-25? | E38: (none) | F38: data | G38: TIKRIKILLA block generated 773,491 person-days during FY 2024-25. This is the highest value recorded for that financial year in the WEST GARO HILLS district. | H38: TIKRIKILLA block generated 773,491 person-days during FY 2024-25. This is the highest value recorded for that financial year in the WEST GARO HILLS district. | I38: SELECT lgd_district, lgd_block, SUM(person_days) AS person_days FROM curated.v_employment WHERE year_key = 2024 GROUP BY lgd_district, lgd_block ORDER BY person_days DESC LIMIT 1 | J38: Top block by person-days | K38: Yes | L38: TIKRIKILLA (773,491) | M38: TIKRIKILLA (773,491) | N38: PASS | O38: TIKRIKILLA, 773,491 = DB = raw. Minor wording: calls it the highest 'in the WEST GARO HILLS district' although it is the statewide top. | P38: DATA-025a.png
A39: DATA-026a | B39: DATA-026 | D39: Which village generated the highest person-days during 2023-24? | E39: (none) | F39: data | G39: The village MAWRYNGKNENG generated 91,425 person-days during FY 2023-24. The record also lists village_code 278380, lgd_district EAST KHASI HILLS, and lgd_block MAWRYNGKNENG. | H39: The village MAWRYNGKNENG generated 91,425 person-days during FY 2023-24. The record also lists village_code 278380, lgd_district EAST KHASI HILLS, and lgd_block MAWRYNGKNENG. | I39: SELECT village_code, lgd_village_name, lgd_district, lgd_block, SUM(person_days) AS person_days FROM curated.v_employment WHERE year_key = 2023 GROUP BY village_code, lgd_village_name, lgd_district, lgd_block ORDER BY person_days DESC LIMIT 1 | J39: Top village by person-days | K39: Yes | L39: MAWRYNGKNENG (91,425) | M39: MAWRYNGKNENG (91,425) | N39: PASS | O39: MAWRYNGKNENG village, 91,425 = DB = raw (checked by village code too). | P39: DATA-026a.png
A40: DATA-026b | B40: DATA-026 | D40: Which village generated the highest person-days during 2022-23? | E40: (none) | F40: data | G40: MAWRYNGKNENG generated 90,017 person-days during FY 2022-23. The record also shows village_code 278380, lgd_district EAST KHASI HILLS, and lgd_block MAWRYNGKNENG. | H40: MAWRYNGKNENG generated 90,017 person-days during FY 2022-23. The record also shows village_code 278380, lgd_district EAST KHASI HILLS, and lgd_block MAWRYNGKNENG. | I40: SELECT village_code, lgd_village_name, lgd_district, lgd_block, SUM(person_days) AS person_days FROM curated.v_employment WHERE year_key = 2022 GROUP BY village_code, lgd_village_name, lgd_district, lgd_block ORDER BY person_days DESC LIMIT 1 | J40: Top village by person-days | K40: Yes | L40: MAWRYNGKNENG (90,017) | M40: MAWRYNGKNENG (90,017) | N40: PASS | O40: MAWRYNGKNENG village, 90,017 = DB = raw. | P40: DATA-026b.png
...

Sheet Defects
A1: # | B1: Defect | C1: Severity | D1: Test cases | E1: Evidence / reproduction | F1: Root cause (where) | G1: Owner
A2: 1 | B2: Block that shares its name with a village (MAWKYRWAT, MAWRYNGKNENG, GAMBEGRE … 26 such names) cannot be queried via the bot's own 'The X block' chip or the phrase '…, the block, not the village': the bot either gives up ('couldn't build a working query') or silently answers with the VILLAGE figure. | C2: Critical | D2: DATA-003, DATA-016, DATA-020, DATA-029 | E2: DATA-016a: 'How many households received employment in MAWKYRWAT during 2024-25, the block, not the village' → 273 (village 277399) instead of 11,590. Same question with 'Mawkyrwat block' → 11,590 (correct). | F2: app/pipeline.py _explicit_level_in: the stated admin level is detected finest-first, so the chip text '…, the block, not the village' was read as level = VILLAGE (the negated word). resolve_entities then pinned village_code 277399; execute_with_repair rejected the block SQL (village-in-block-column guard) or the SQL used the village code. | G2: Bot (AI team)
A3: 2 | B3: Assembly constituency SOUTH TURA rejected as out-of-scope (edge 'I can only answer questions about those schemes…'). | C3: High | D3: DATA-004, DATA-014 | E3: 'How many persons received employment in SOUTH TURA during 2024-25?' → edge reply. Expected 152 persons (village SANGSANGGRE). Note: raw + DB have only 2 SOUTH TURA rows statewide; most Tura urban villages are not in the employment data. | F3: Edge / scope layer does not recognise SOUTH TURA as a Meghalaya place (probably the 'South …' / 'Tura' handling); GAMBEGRE and NONGKREM constituencies work. | G3: Bot (AI team)
A4: 3 | B4: Bot asks 'Which scheme does your question concern?' for measures that exist only in MGNREGA (materials, wages, women employment, employment %, village lists, 'employment generated'). | C4: Medium | D4: DATA-011, DATA-014, DATA-017, DATA-019, DATA-023, DATA-030 | E4: Numbers are correct after the officer picks MGNREGA, but the extra step is the exact complaint in the 21 Sep sheet. Inconsistent: village-level 'women were provided employment' does NOT ask, district-level 'women received employment' DOES. | F4: Scheme gate (scheme-not-specified) — MGNREGA-only vocabulary is not treated as a scheme signal at district level. | G4: Bot (AI team)
A5: 4 | B5: Average person-days per household truncated to an integer (38.00 instead of 38.16). | C5: High | D5: DATA-021 | E5: SQL: ROUND(SUM(person_days) / NULLIF(SUM(households_employed),0), 2) — both BIGINT, so Postgres integer-divides. DB = raw: 1,632,188 / 42,770 = 38.16. | F5: SQL generation: needs 1.0 * / ::numeric (rule + few-shot + deterministic guard per CLAUDE.md §5). | G5: Bot (AI team)
A6: 5 | B6: 'Which villages in <constituency> received employment' returns village CODES, not names, and counts villages with zero employment. | C6: High | D6: DATA-014 | E6: NONGKREM 2024-25: bot says 'Four villages … received employment' (codes 278375, 278386, 278399, 278424). DB = raw: only URMASI-U-JOH had employment (66 persons); 3 villages have 0. | F6: SQL: SELECT DISTINCT village_code … with no persons_employed > 0 filter and no lgd_village_name. | G6: Bot (AI team)
A7: 6 | B7: Wage vs material comparison answered without any figures (and once claims figures are not available). | C7: Medium | D7: DATA-023 | E7: JAKREM 2024-25: 'Wages were the higher spending category … with no specific monetary figures provided in the available data.' Actual: wages 219.48 lakh vs material 113.89 lakh. | F7: SQL returns only a CASE label ('wages'), so the composer has no numbers. | G7: Bot (AI team)
A8: 7 | B8: 'How much was spent and how many person-days … in <village>' routed to the reference-document (RAG) path; village treated as a scheme name. | C8: High | D8: DATA-028 | E8: JAKREM 2024-25 → 'reference material does not contain … the JAKREM scheme'. Expected 333.37 lakh + 57,391 person-days. | F8: Intent classifier (DATA vs KNOWLEDGE) for combined money + person-days questions. | G8: Bot (AI team)
A9: 8 | B9: Block expenditure + person-days comparison is intermittent: 1 of 5 runs answer. | C9: High | D9: DATA-029 | E9: Correct when it answers (942.59 lakh, 164,650 person-days = DB = raw). Otherwise 'couldn't build a working query'. Same 'the block, not …' phrasing as defect 1. | F9: Defect 1 plus SQL generation variability on the two-CTE pattern. | G9: Bot (AI team)
A10: 9 | B10: Administrative expenditure: bot refuses instead of reporting 0.00 lakh. | C10: Low (product decision) | D10: DATA-013 | E10: Bot's statement is accurate: Adm_Exp_Total is 0 on every row except one statewide (0.90 lakh) in both DB and raw. The test sheet expects the aggregate figure. | F10: By design: schema_context MGNREGA rule 10 / column-not-held gate. Decide: answer '0.00 lakh (column not populated at source)' or keep refusing. | G10: Product / SME
A11: 10 | B11: DB geography mapping differs from the raw file for village GENAPARA (code 274268): raw = PURAKHASIA block, South West Garo Hills; DB = DALU block, West Garo Hills. | C11: Medium (data) | D11: Affects DATA-019, DATA-027, DATA-030 (West Garo Hills figures) — all district/block employment totals for WGH, SWGH, DALU, PURAKHASIA | E11: Employment only; all 4 years. WGH 2024-25 persons 56,774 (DB) vs 56,733 (raw); person-days 2,808,417 vs 2,806,403. Statewide totals identical. Expenditure: no difference. | F11: curated.v_employment geography_key for village_code 274268 (ingestion). Raw Match_Method = 'Via shifted-village list' for 3 of 4 years. | G11: Data team (megh-ingestion)
A12: 11 | B12: Composer wording issues (numbers correct): '6.67 completion 100 day pct.'; '585 households completed 100 days.' (no place/year); 'highest … in the WEST GARO HILLS district' for a statewide top; 'the only district recorded' for a LIMIT 1 result; expenditure unit switches between lakh and crore across runs. | C12: Low | D12: DATA-020b, DATA-009, DATA-025, DATA-027, DATA-002b | E12: See Variant Detail sheet. | F12: compose_response prompt / templates. | G12: Bot (AI team)
A13: 12 | B13: Raw data observation: 'Women Employment Provided' is 0 on every row for FY 2025-26 (statewide 0) — any FY 2025-26 women figure will be 0. | C13: Info (data) | D13: DATA-008/017/019/027 if asked for 2025-26 | E13: Raw and DB both 0 for 2025-26; 2022-23…2024-25 populated. | F13: Source data. | G13: Data team / SME

Sheet DB vs Raw
A1: DB (megh_db.curated.v_employment / v_expenditure) vs raw CSV reconciliation
A2: Raw: 'MGNREGA_Combined - MGNREGA Employment.csv' (26,375 rows) and 'MGNREGA_Combined - MGNREGA Expenditure.csv' (18,818 rows). DB queried read-only on 2026-09-26. Compared at district × FY × measure grain (336 cells per source) plus statewide totals.
A4: Source | B4: Measure | C4: Raw CSV total | D4: megh_db total | E4: Difference (formula) | F4: Match?
A5: Employment | B5: Row count | C5: 26375 | D5: 26375 | E5: =D5-C5 -> 0 | F5: =IF(ABS(E5)<0.005,"Yes","No") -> Yes
A6: Employment | B6: Employment Provided Households | C6: 1494437 | D6: 1494437 | E6: =D6-C6 -> 0 | F6: =IF(ABS(E6)<0.005,"Yes","No") -> Yes
A7: Employment | B7: Employment Provided Persons | C7: 1865234 | D7: 1865234 | E7: =D7-C7 -> 0 | F7: =IF(ABS(E7)<0.005,"Yes","No") -> Yes
A8: Employment | B8: Employment Provided Total Person Days | C8: 90915181 | D8: 90915181 | E8: =D8-C8 -> 0 | F8: =IF(ABS(E8)<0.005,"Yes","No") -> Yes
A9: Employment | B9: Households Completed 100 Days Work | C9: 171125 | D9: 171125 | E9: =D9-C9 -> 0 | F9: =IF(ABS(E9)<0.005,"Yes","No") -> Yes
A10: Employment | B10: Job Cards Issued Total | C10: 2128714 | D10: 2128714 | E10: =D10-C10 -> 0 | F10: =IF(ABS(E10)<0.005,"Yes","No") -> Yes
A11: Employment | B11: Women Employment Provided | C11: 834416 | D11: 834416 | E11: =D11-C11 -> 0 | F11: =IF(ABS(E11)<0.005,"Yes","No") -> Yes
A12: Expenditure (lakh ₹) | B12: Row count | C12: 18818 | D12: 18818 | E12: =D12-C12 -> 0 | F12: =IF(ABS(E12)<0.005,"Yes","No") -> Yes
A13: Expenditure (lakh ₹) | B13: Total_Exp | C13: 362866.57 | D13: 362866.57 | E13: =D13-C13 -> 0 | F13: =IF(ABS(E13)<0.005,"Yes","No") -> Yes
A14: Expenditure (lakh ₹) | B14: Exp_Unskilled_Wage | C14: 231101.97 | D14: 231101.97 | E14: =D14-C14 -> 0 | F14: =IF(ABS(E14)<0.005,"Yes","No") -> Yes
A15: Expenditure (lakh ₹) | B15: Exp_Semi_Skilled_Wage | C15: 14782.94 | D15: 14782.94 | E15: =D15-C15 -> 0 | F15: =IF(ABS(E15)<0.005,"Yes","No") -> Yes
A16: Expenditure (lakh ₹) | B16: Exp_Material | C16: 114327.81 | D16: 114327.81 | E16: =D16-C16 -> 0 | F16: =IF(ABS(E16)<0.005,"Yes","No") -> Yes
... A18: Expenditure (lakh ₹) | B18: Adm_Exp_Total | C18: 0.9 | D18: 0.9 | E18: =D18-C18 -> 0 | F18: =IF(ABS(E18)<0.005,"Yes","No") -> Yes
A20: Cell-level differences (district × FY × measure) — all caused by ONE village, GENAPARA (village_code 274268)
A21: Raw: GENAPARA, PURAKHASIA block, SOUTH WEST GARO HILLS (Match_Method 'Via shifted-village list' for 2022-23…2024-25). DB: GENAPARA, DALU block, WEST GARO HILLS. Expenditure: 336/336 cells match. Employment: 286/336 match; the 50 below differ.
A22: Source | B22: District | C22: FY | D22: Measure | E22: Raw | F22: DB | G22: DB − Raw
A23: Employment | B23: SOUTH WEST GARO HILLS | C23: 2022-23 | D23: n | E23: 514 | F23: 513 | G23: =F23-E23 -> -1
A24: Employment | B24: SOUTH WEST GARO HILLS | C24: 2023-24 | D24: n | E24: 512 | F24: 511 | G24: =F24-E24 -> -1
A25: Employment | B25: SOUTH WEST GARO HILLS | C25: 2024-25 | D25: n | E25: 588 | F25: 587 | G25: =F25-E25 -> -1
A26: Employment | B26: SOUTH WEST GARO HILLS | C26: 2025-26 | D26: n | E26: 600 | F26: 599 | G26: =F26-E26 -> -1
A27: Employment | B27: WEST GARO HILLS | C27: 2022-23 | D27: n | E27: 957 | F27: 958 | G27: =F27-E27 -> 1
A28: Employment | B28: WEST GARO HILLS | C28: 2023-24 | D28: n | E28: 953 | F28: 954 | G28: =F28-E28 -> 1
A29: Employment | B29: WEST GARO HILLS | C29: 2024-25 | D29: n | E29: 1048 | F29: 1049 | G29: =F29-E29 -> 1
A30: Employment | B30: WEST GARO HILLS | C30: 2025-26 | D30: n | E30: 1060 | F30: 1061 | G30: =F30-E30 -> 1
A31: Employment | B31: SOUTH WEST GARO HILLS | C31: 2022-23 | D31: Employment Provided Households | E31: 43336 | F31: 43189 | G31: =F31-E31 -> -147
A32: Employment | B32: SOUTH WEST GARO HILLS | C32: 2023-24 | D32: Employment Provided Households | E32: 44092 | F32: 43955 | G32: =F32-E32 -> -137
A33: Employment | B33: SOUTH WEST GARO HILLS | C33: 2024-25 | D33: Employment Provided Households | E33: 35859 | F33: 35833 | G33: =F33-E33 -> -26
A34: Employment | B34: SOUTH WEST GARO HILLS | C34: 2025-26 | D34: Employment Provided Households | E34: 42134 | F34: 41999 | G34: =F34-E34 -> -135
... A72: Employment | B72: WEST GARO HILLS | C72: 2024-25 | D72: Women Employment Provided | E72: 29865 | F72: 29890 | G72: =F72-E72 -> 25

Sheet Evidence
B1: Evidence — one capture per tested query (same graded run). Files also in docs/MGNREGA_UseCase_Evidence_2026-09-26
B3: DATA-001a (DATA-001a.png)
B34: DATA-001b (DATA-001b.png)
B65: DATA-001c (DATA-001c.png)
B97: DATA-002a (DATA-002a.png)
B128: DATA-002b (DATA-002b.png)
B159: DATA-003a (DATA-003a.png)
